<?xml version="1.0" ?>
<sdf version="1.8">
  <model name="service_robot">
    <frame name="lidar_frame" attached_to="chassis">
      <pose>0.8 0 0.5 0 0 0</pose>
    </frame>

    <frame name="camera_frame" attached_to="chassis">
      <pose>0.95 0 0.58 0 0 0</pose>
    </frame>

    <frame name="camera_left_frame" attached_to="chassis">
      <pose>0.95 0 0.58 0 0 0.785398</pose>
    </frame>

    <frame name="camera_right_frame" attached_to="chassis">
      <pose>0.95 0 0.58 0 0 -0.785398</pose>
    </frame>

    <frame name="camera_back_frame" attached_to="chassis">
      <pose>-0.4 0 0.58 0 0 3.141593</pose>
    </frame>

    <frame name="imu_frame" attached_to="chassis">
      <pose>0 0 0.15 0 0 0</pose>
    </frame>

    <link name="chassis">
      <pose relative_to="__model__">0.5 0 0.4 0 0 0</pose>
      <inertial>
        <mass>1.14395</mass>
        <inertia>
          <ixx>0.095329</ixx>
          <ixy>0</ixy>
          <ixz>0</ixz>
          <iyy>0.381317</iyy>
          <iyz>0</iyz>
          <izz>0.476646</izz>
        </inertia>
      </inertial>

      <visual name="visual">
        <geometry>
          <box>
            <size>2.0 1.0 0.5</size>
          </box>
        </geometry>
        <material>
          <ambient>0.0 0.0 1.0 1</ambient>
          <diffuse>0.0 0.0 1.0 1</diffuse>
          <specular>0.0 0.0 1.0 1</specular>
        </material>
      </visual>

      <collision name="collision">
        <geometry>
          <box>
            <size>2.0 1.0 0.5</size>
          </box>
        </geometry>
      </collision>
      <!-- Bumper collisions (thin shells just outside the chassis box) -->
      <collision name="bumper_front_col">
        <pose>1.025 0 0 0 0 0</pose>
        <geometry>
          <box><size>0.05 1.0 0.5</size></box>
        </geometry>
      </collision>
      <collision name="bumper_rear_col">
        <pose>-1.025 0 0 0 0 0</pose>
        <geometry>
          <box><size>0.05 1.0 0.5</size></box>
        </geometry>
      </collision>
      <collision name="bumper_left_col">
        <pose>0 0.525 0 0 0 0</pose>
        <geometry>
          <box><size>2.0 0.05 0.5</size></box>
        </geometry>
      </collision>
      <collision name="bumper_right_col">
        <pose>0 -0.525 0 0 0 0</pose>
        <geometry>
          <box><size>2.0 0.05 0.5</size></box>
        </geometry>
      </collision>
      <!-- Bumper contact sensors -->
      <sensor name="bumper_front" type="contact">
        <update_rate>30</update_rate>
        <always_on>true</always_on>
        <topic>bumper/front</topic>
        <contact>
          <collision>bumper_front_col</collision>
        </contact>
      </sensor>
      <sensor name="bumper_rear" type="contact">
        <update_rate>30</update_rate>
        <always_on>true</always_on>
        <topic>bumper/rear</topic>
        <contact>
          <collision>bumper_rear_col</collision>
        </contact>
      </sensor>
      <sensor name="bumper_left" type="contact">
        <update_rate>30</update_rate>
        <always_on>true</always_on>
        <topic>bumper/left</topic>
        <contact>
          <collision>bumper_left_col</collision>
        </contact>
      </sensor>
      <sensor name="bumper_right" type="contact">
        <update_rate>30</update_rate>
        <always_on>true</always_on>
        <topic>bumper/right</topic>
        <contact>
          <collision>bumper_right_col</collision>
        </contact>
      </sensor>

      <!-- 2D planar LiDAR for SLAM / Nav2 -->
      <sensor name="planar_lidar" type="gpu_lidar">
        <pose relative_to="lidar_frame">0 0 0 0 0 0</pose>
        <topic>scan</topic>
        <gz_frame_id>lidar_frame</gz_frame_id>
        <update_rate>30</update_rate>
        <always_on>true</always_on>
        <visualize>true</visualize>
        <lidar>
          <scan>
            <horizontal>
              <samples>720</samples>
              <resolution>1</resolution>
              <min_angle>-3.14159265359</min_angle>
              <max_angle>3.14159265359</max_angle>
            </horizontal>
            <vertical>
              <samples>1</samples>
              <resolution>1</resolution>
              <min_angle>0</min_angle>
              <max_angle>0</max_angle>
            </vertical>
          </scan>
          <range>
            <min>0.12</min>
            <max>20.0</max>
            <resolution>0.01</resolution>
          </range>
        </lidar>
      </sensor>

      <!-- Forward camera for QR-code landmark detection only -->
      <sensor name="front_camera" type="camera">
        <pose relative_to="camera_frame">0 0 0 0 0 0</pose>
        <topic>camera/image_raw</topic>
        <gz_frame_id>camera_frame</gz_frame_id>
        <update_rate>20</update_rate>
        <always_on>true</always_on>
        <visualize>true</visualize>
        <camera name="front_camera_sensor">
          <camera_info_topic>camera/camera_info</camera_info_topic>
          <horizontal_fov>1.3962634</horizontal_fov>
          <image>
            <width>640</width>
            <height>480</height>
            <format>R8G8B8</format>
          </image>
          <clip>
            <near>0.05</near>
            <far>50.0</far>
          </clip>
        </camera>
      </sensor>

      <!-- Left side camera (+45 deg yaw) for QR coverage -->
      <sensor name="camera_left" type="camera">
        <pose relative_to="camera_left_frame">0 0 0 0 0 0</pose>
        <topic>camera_left/image_raw</topic>
        <gz_frame_id>camera_left_frame</gz_frame_id>
        <update_rate>20</update_rate>
        <always_on>true</always_on>
        <visualize>true</visualize>
        <camera name="camera_left_sensor">
          <camera_info_topic>camera_left/camera_info</camera_info_topic>
          <horizontal_fov>1.3962634</horizontal_fov>
          <image>
            <width>640</width>
            <height>480</height>
            <format>R8G8B8</format>
          </image>
          <clip>
            <near>0.05</near>
            <far>50.0</far>
          </clip>
        </camera>
      </sensor>

      <!-- Right side camera (-45 deg yaw) for QR coverage -->
      <sensor name="camera_right" type="camera">
        <pose relative_to="camera_right_frame">0 0 0 0 0 0</pose>
        <topic>camera_right/image_raw</topic>
        <gz_frame_id>camera_right_frame</gz_frame_id>
        <update_rate>20</update_rate>
        <always_on>true</always_on>
        <visualize>true</visualize>
        <camera name="camera_right_sensor">
          <camera_info_topic>camera_right/camera_info</camera_info_topic>
          <horizontal_fov>1.3962634</horizontal_fov>
          <image>
            <width>640</width>
            <height>480</height>
            <format>R8G8B8</format>
          </image>
          <clip>
            <near>0.05</near>
            <far>50.0</far>
          </clip>
        </camera>
      </sensor>

      <!-- Rear camera (180 deg yaw) for QR coverage -->
      <sensor name="camera_back" type="camera">
        <pose relative_to="camera_back_frame">0 0 0 0 0 0</pose>
        <topic>camera_back/image_raw</topic>
        <gz_frame_id>camera_back_frame</gz_frame_id>
        <update_rate>20</update_rate>
        <always_on>true</always_on>
        <visualize>true</visualize>
        <camera name="camera_back_sensor">
          <camera_info_topic>camera_back/camera_info</camera_info_topic>
          <horizontal_fov>1.3962634</horizontal_fov>
          <image>
            <width>640</width>
            <height>480</height>
            <format>R8G8B8</format>
          </image>
          <clip>
            <near>0.05</near>
            <far>50.0</far>
          </clip>
        </camera>
      </sensor>

      <!-- IMU for filtered odometry / heading stabilization -->
      <sensor name="imu_sensor" type="imu">
        <pose relative_to="imu_frame">0 0 0 0 0 0</pose>
        <topic>imu</topic>
        <gz_frame_id>imu_frame</gz_frame_id>
        <update_rate>100</update_rate>
        <always_on>true</always_on>
        <visualize>false</visualize>

        <imu>
          <angular_velocity>
            <x><noise type="none"/></x>
            <y><noise type="none"/></y>
            <z><noise type="none"/></z>
          </angular_velocity>
          <linear_acceleration>
            <x><noise type="none"/></x>
            <y><noise type="none"/></y>
            <z><noise type="none"/></z>
          </linear_acceleration>
        </imu>
      </sensor>
    </link>

    <link name="left_wheel">
      <pose relative_to="chassis">-0.5 0.6 0 -1.5707 0 0</pose>
      <inertial>
        <mass>1</mass>
        <inertia>
          <ixx>0.043333</ixx>
          <ixy>0</ixy>
          <ixz>0</ixz>
          <iyy>0.043333</iyy>
          <iyz>0</iyz>
          <izz>0.08</izz>
        </inertia>
      </inertial>
      <visual name="visual">
        <geometry>
          <cylinder>
            <radius>0.4</radius>
            <length>0.2</length>
          </cylinder>
        </geometry>
        <material>
          <ambient>1.0 0.0 0.0 1</ambient>
          <diffuse>1.0 0.0 0.0 1</diffuse>
          <specular>1.0 0.0 0.0 1</specular>
        </material>
      </visual>
      <collision name="collision">
        <geometry>
          <cylinder>
            <radius>0.4</radius>
            <length>0.2</length>
          </cylinder>
        </geometry>
      </collision>
    </link>

    <link name="right_wheel">
      <pose relative_to="chassis">-0.5 -0.6 0 -1.5707 0 0</pose>
      <inertial>
        <mass>1</mass>
        <inertia>
          <ixx>0.043333</ixx>
          <ixy>0</ixy>
          <ixz>0</ixz>
          <iyy>0.043333</iyy>
          <iyz>0</iyz>
          <izz>0.08</izz>
        </inertia>
      </inertial>
      <visual name="visual">
        <geometry>
          <cylinder>
            <radius>0.4</radius>
            <length>0.2</length>
          </cylinder>
        </geometry>
        <material>
          <ambient>1.0 0.0 0.0 1</ambient>
          <diffuse>1.0 0.0 0.0 1</diffuse>
          <specular>1.0 0.0 0.0 1</specular>
        </material>
      </visual>
      <collision name="collision">
        <geometry>
          <cylinder>
            <radius>0.4</radius>
            <length>0.2</length>
          </cylinder>
        </geometry>
      </collision>
    </link>

    <frame name="caster_frame" attached_to="chassis">
      <pose>0.8 0 -0.2 0 0 0</pose>
    </frame>

    <link name="caster">
      <pose relative_to="caster_frame"/>
      <inertial>
        <mass>1</mass>
        <inertia>
          <ixx>0.016</ixx>
          <ixy>0</ixy>
          <ixz>0</ixz>
          <iyy>0.016</iyy>
          <iyz>0</iyz>
          <izz>0.016</izz>
        </inertia>
      </inertial>
      <visual name="visual">
        <geometry>
          <sphere>
            <radius>0.2</radius>
          </sphere>
        </geometry>
        <material>
          <ambient>0.0 1 0.0 1</ambient>
          <diffuse>0.0 1 0.0 1</diffuse>
          <specular>0.0 1 0.0 1</specular>
        </material>
      </visual>
      <collision name="collision">
        <geometry>
          <sphere>
            <radius>0.2</radius>
          </sphere>
        </geometry>
      </collision>
    </link>

    <joint name="left_wheel_joint" type="revolute">
      <pose relative_to="left_wheel"/>
      <parent>chassis</parent>
      <child>left_wheel</child>
      <axis>
        <xyz expressed_in="__model__">0 1 0</xyz>
        <limit>
          <lower>-1.79769e+308</lower>
          <upper>1.79769e+308</upper>
        </limit>
      </axis>
    </joint>

    <joint name="right_wheel_joint" type="revolute">
      <pose relative_to="right_wheel"/>
      <parent>chassis</parent>
      <child>right_wheel</child>
      <axis>
        <xyz expressed_in="__model__">0 1 0</xyz>
        <limit>
          <lower>-1.79769e+308</lower>
          <upper>1.79769e+308</upper>
        </limit>
      </axis>
    </joint>

    <joint name="caster_wheel" type="ball">
      <parent>chassis</parent>
      <child>caster</child>
    </joint>

    <plugin filename="gz-sim-diff-drive-system" name="gz::sim::systems::DiffDrive">
      <left_joint>left_wheel_joint</left_joint>
      <right_joint>right_wheel_joint</right_joint>
      <wheel_separation>1.2</wheel_separation>
      <wheel_radius>0.4</wheel_radius>
      <odom_publish_frequency>30</odom_publish_frequency>
      <topic>cmd_vel</topic>
      <odom_topic>odom</odom_topic>
      <tf_topic>tf</tf_topic>
      <frame_id>odom</frame_id>
      <child_frame_id>chassis</child_frame_id>
    </plugin>
  </model>
</sdf>
